Workbook

Sheet Material
B1: 169
B2: ID | C2: Mtype | D2: StandardID | E2: Mstandard | F2: Mname | G2: M_g_cm3 | H2: type | I2: 最低冲击温度 | J2: 标准冲击温度 | K2: KV2 | L2: 配套材料
B3: 0 | C3: 板材 | D3: 48 | E3: =VLOOKUP(D3,Standard!$B$2:$D$251,2,FALSE) -> GB/T 713.2-2023 | F3: Q245R | G3: 7.85 | H3: CS | I3: -20 | J3: 0 | K3: 34 | L3: 39,92
B4: 1 | C4: 板材 | D4: 48 | E4: =VLOOKUP(D4,Standard!$B$2:$D$251,2,FALSE) -> GB/T 713.2-2023 | F4: Q345R | G4: 7.85 | H4: CS | I4: -20 | J4: 0 | K4: 41 | L4: 48,94
B5: 2 | C5: 板材 | D5: 48 | E5: =VLOOKUP(D5,Standard!$B$2:$D$251,2,FALSE) -> GB/T 713.2-2023 | F5: Q370R | G5: 7.85 | H5: CS | I5: -20 | J5: -20 | K5: 47 | L5: 49,95
B6: 3 | C6: 板材 | D6: 48 | E6: =VLOOKUP(D6,Standard!$B$2:$D$251,2,FALSE) -> GB/T 713.2-2023 | F6: 18MnMoNbR | G6: 7.85 | H6: CS | I6: -10 | J6: 0 | K6: 47 | L6: 49,96
B7: 4 | C7: 板材 | D7: 48 | E7: =VLOOKUP(D7,Standard!$B$2:$D$251,2,FALSE) -> GB/T 713.2-2023 | F7: 13MnNiMoR | G7: 7.85 | H7: CS | I7: -20 | J7: 0 | K7: 47 | L7: 49,95
B8: 5 | C8: 板材 | D8: 48 | E8: =VLOOKUP(D8,Standard!$B$2:$D$251,2,FALSE) -> GB/T 713.2-2023 | F8: 15CrMoR | G8: 7.85 | H8: CS | I8: -20 | J8: 20 | K8: 47 | L8: 42,99
B9: 6 | C9: 板材 | D9: 48 | E9: =VLOOKUP(D9,Standard!$B$2:$D$251,2,FALSE) -> GB/T 713.2-2023 | F9: 14Cr1MoR | G9: 7.85 | H9: CS | I9: -20 | J9: 20 | K9: 47 | L9: 43,100
B10: 7 | C10: 板材 | D10: 48 | E10: =VLOOKUP(D10,Standard!$B$2:$D$251,2,FALSE) -> GB/T 713.2-2023 | F10: 12Cr2Mo1R | G10: 7.85 | H10: CS | I10: -20 | J10: 20 | K10: 47 | L10: 44,101
B11: 8 | C11: 板材 | D11: 48 | E11: =VLOOKUP(D11,Standard!$B$2:$D$251,2,FALSE) -> GB/T 713.2-2023 | F11: 12Cr1Mo1VR | G11: 7.85 | H11: CS | I11: -20 | J11: -20 | K11: 60 | L11: 44,102
B12: 9 | C12: 板材 | D12: 49 | E12: =VLOOKUP(D12,Standard!$B$2:$D$251,2,FALSE) -> GB/T 713.3-2023 | F12: 16MnDR | G12: 7.85 | H12: CS | I12: -40 | J12: -30 | K12: 47 | L12: 49,105
B13: 10 | C13: 板材 | D13: 49 | E13: =VLOOKUP(D13,Standard!$B$2:$D$251,2,FALSE) -> GB/T 713.3-2023 | F13: 15MnNiDR | G13: 7.85 | H13: CS | I13: -45 | J13: -45 | K13: 60 | L13: 49,106
B14: 11 | C14: 板材 | D14: 49 | E14: =VLOOKUP(D14,Standard!$B$2:$D$251,2,FALSE) -> GB/T 713.3-2023 | F14: 15MnNiNbDR | G14: 7.85 | H14: CS | I14: -50 | J14: -50 | K14: 60 | L14: 49,108
... B16: 13 | C16: 板材 | D16: 49 | E16: =VLOOKUP(D16,Standard!$B$2:$D$251,2,FALSE) -> GB/T 713.3-2023 | F16: 08Ni3DR | G16: 7.85 | H16: CS | I16: -100 | J16: -100 | K16: 60 | L16: 110
B17: 14 | C17: 板材 | D17: 49 | E17: =VLOOKUP(D17,Standard!$B$2:$D$251,2,FALSE) -> GB/T 713.3-2023 | F17: 06Ni9DR | G17: 7.89 | H17: CS | I17: -196 | J17: -196 | K17: 100
B18: 15 | C18: 板材 | D18: 33 | E18: =VLOOKUP(D18,Standard!$B$2:$D$251,2,FALSE) -> GB/T 713.6-2023 | F18: 07MnMoVR | G18: 7.85 | H18: CS | I18: -20 | J18: -20 | K18: 80
B19: 16 | C19: 板材 | D19: 33 | E19: =VLOOKUP(D19,Standard!$B$2:$D$251,2,FALSE) -> GB/T 713.6-2023 | F19: 07MnNiVDR | G19: 7.85 | H19: CS | I19: -40 | J19: -40 | K19: 80
B20: 17 | C20: 板材 | D20: 33 | E20: =VLOOKUP(D20,Standard!$B$2:$D$251,2,FALSE) -> GB/T 713.6-2023 | F20: 07MnNiMoDR | G20: 7.85 | H20: CS | I20: -50 | J20: -50 | K20: 80
B21: 18 | C21: 板材 | D21: 33 | E21: =VLOOKUP(D21,Standard!$B$2:$D$251,2,FALSE) -> GB/T 713.6-2023 | F21: 12MnNiVR | G21: 7.85 | H21: CS | I21: -20 | J21: -20 | K21: 80
B22: 19 | C22: 板材 | D22: 37 | E22: =VLOOKUP(D22,Standard!$B$2:$D$251,2,FALSE) -> GB/T 713.7-2023 | F22: S11306 | G22: 7.75 | H22: SS
B23: 20 | C23: 板材 | D23: 37 | E23: =VLOOKUP(D23,Standard!$B$2:$D$251,2,FALSE) -> GB/T 713.7-2023 | F23: S11348 | G23: 7.75 | H23: SS
B24: 21 | C24: 板材 | D24: 37 | E24: =VLOOKUP(D24,Standard!$B$2:$D$251,2,FALSE) -> GB/T 713.7-2023 | F24: S11972 | G24: 7.75 | H24: SS
B25: 22 | C25: 板材 | D25: 37 | E25: =VLOOKUP(D25,Standard!$B$2:$D$251,2,FALSE) -> GB/T 713.7-2023 | F25: S21953 | G25: 7.7 | H25: SS
B26: 23 | C26: 板材 | D26: 37 | E26: =VLOOKUP(D26,Standard!$B$2:$D$251,2,FALSE) -> GB/T 713.7-2023 | F26: S22253 | G26: 7.8 | H26: SS | L26: 76,122
B27: 24 | C27: 板材 | D27: 37 | E27: =VLOOKUP(D27,Standard!$B$2:$D$251,2,FALSE) -> GB/T 713.7-2023 | F27: S22053 | G27: 7.8 | H27: SS | L27: 77,123
B28: 25 | C28: 板材 | D28: 37 | E28: =VLOOKUP(D28,Standard!$B$2:$D$251,2,FALSE) -> GB/T 713.7-2023 | F28: S30408 | G28: 7.93 | H28: SS | L28: 57,111
B29: 26 | C29: 板材 | D29: 37 | E29: =VLOOKUP(D29,Standard!$B$2:$D$251,2,FALSE) -> GB/T 713.7-2023 | F29: S30403 | G29: 7.9 | H29: SS | L29: 59,112
B30: 27 | C30: 板材 | D30: 37 | E30: =VLOOKUP(D30,Standard!$B$2:$D$251,2,FALSE) -> GB/T 713.7-2023 | F30: S30409 | G30: 7.9 | H30: SS | L30: 74,113
B31: 28 | C31: 板材 | D31: 37 | E31: =VLOOKUP(D31,Standard!$B$2:$D$251,2,FALSE) -> GB/T 713.7-2023 | F31: S31008 | G31: 7.98 | H31: SS | L31: 73,114
B32: 29 | C32: 板材 | D32: 37 | E32: =VLOOKUP(D32,Standard!$B$2:$D$251,2,FALSE) -> GB/T 713.7-2023 | F32: S31608 | G32: 8 | H32: SS | L32: 63,115
B33: 30 | C33: 板材 | D33: 37 | E33: =VLOOKUP(D33,Standard!$B$2:$D$251,2,FALSE) -> GB/T 713.7-2023 | F33: S31603 | G33: 8 | H33: SS | L33: 65,116
B34: 31 | C34: 板材 | D34: 37 | E34: =VLOOKUP(D34,Standard!$B$2:$D$251,2,FALSE) -> GB/T 713.7-2023 | F34: S31668 | G34: 7.9 | H34: SS | L34: 67,117
B35: 32 | C35: 板材 | D35: 37 | E35: =VLOOKUP(D35,Standard!$B$2:$D$251,2,FALSE) -> GB/T 713.7-2023 | F35: S31708 | G35: 8 | H35: SS | L35: 69,118
B36: 33 | C36: 板材 | D36: 37 | E36: =VLOOKUP(D36,Standard!$B$2:$D$251,2,FALSE) -> GB/T 713.7-2023 | F36: S31703 | G36: 7.98 | H36: SS | L36: 71,118 | P36: GB/T 6479-2013
B37: 34 | C37: 板材 | D37: 37 | E37: =VLOOKUP(D37,Standard!$B$2:$D$251,2,FALSE) -> GB/T 713.7-2023 | F37: S32168 | G37: 8 | H37: SS | L37: 61,119
B38: 35 | C38: 板材 | D38: 37 | E38: =VLOOKUP(D38,Standard!$B$2:$D$251,2,FALSE) -> GB/T 713.7-2023 | F38: S39042 | G38: 8 | H38: SS | L38: 120 | P38: GB/T 14976-2012
B39: 36 | C39: 管材 | D39: 60 | E39: =VLOOKUP(D39,Standard!$B$2:$D$251,2,FALSE) -> GB/T 8163-2008 | F39: 10 | G39: 7.85 | H39: CS | I39: -10 | K39: 31 | N39: =VLOOKUP(D39,Standard!$B$2:$D$251,3,FALSE) -> 输送流体用无缝钢管
B40: 37 | C40: 管材 | D40: 60 | E40: =VLOOKUP(D40,Standard!$B$2:$D$251,2,FALSE) -> GB/T 8163-2008 | F40: 20 | G40: 7.85 | H40: CS | I40: 0 | K40: 31
B41: 38 | C41: 管材 | D41: 60 | E41: =VLOOKUP(D41,Standard!$B$2:$D$251,2,FALSE) -> GB/T 8163-2008 | F41: Q345D | G41: 7.85 | H41: CS | I41: -20 | K41: 34
...

Sheet SMaterial
B1: 85
B2: ID | C2: Mtype | D2: StandardID | E2: Mstandard | F2: Mname | G2: M_g_cm3 | H2: type
B3: 1 | C3: 不锈钢复合 | F3: S11306 | G3: 7.75 | H3: SS
B4: 2 | C4: 不锈钢复合 | F4: S11348 | G4: 7.75 | H4: SS
B5: 3 | C5: 不锈钢复合 | F5: S11972 | G5: 7.75 | H5: SS
B6: 4 | C6: 不锈钢复合 | F6: S21953 | G6: 7.7 | H6: SS
B7: 5 | C7: 不锈钢复合 | F7: S22253 | G7: 7.8 | H7: SS
B8: 6 | C8: 不锈钢复合 | F8: S22053 | G8: 7.8 | H8: SS
B9: 7 | C9: 不锈钢复合 | F9: S30408 | G9: 7.93 | H9: SS
B10: 8 | C10: 不锈钢复合 | F10: S30403 | G10: 7.9 | H10: SS
B11: 9 | C11: 不锈钢复合 | F11: S30409 | G11: 7.9 | H11: SS
B12: 10 | C12: 不锈钢复合 | F12: S31008 | G12: 7.98 | H12: SS
B13: 11 | C13: 不锈钢复合 | F13: S31608 | G13: 8 | H13: SS
B14: 12 | C14: 不锈钢复合 | F14: S31603 | G14: 8 | H14: SS
... B87: 85 | C87: 垫板 | F87: TA10 | G87: 4.56 | H87: Ti

Sheet Standard
B1: 251 | D1: 注：ID号码不能更改了 | F1: 设计制造与检验标准
B2: 1 | C2: GB 4053.1-2009 | D2: 固定式钢梯及平台安全要求 第1部分 钢直梯 | F2: 231
B3: 2 | C3: GB 4053.2-2009 | D3: 固定式钢梯及平台安全要求 第2部分 钢斜梯 | F3: 21
B4: 3 | C4: GB 4053.3-2009 | D4: 固定式钢梯及平台安全要求 第3部分：工业防护栏杆及钢平台 | F4: 27
B5: 4 | C5: GB 50009-2012 | D5: 建筑结构荷载规范 | F5: 209
B6: 5 | C6: GB 50011-2010 | D6: 建筑抗震设计规范 | F6: 210
B7: 6 | C7: GB 50017-2003 | D7: 钢结构设计规范 | F7: 14
B8: 7 | C8: GB 50094-2010 | D8: 球形储罐施工规范 | F8: 148
B9: 8 | C9: GB 6178-1986 | D9: 1型六角开槽螺母--A和B级 | F9: 51
B10: 9 | C10: GB 6181-1986 | D10: 六角开槽薄螺母--A和B级 | F10: 52
B11: 10 | C11: GB/T 1031-2009 | D11: 产品几何技术规范(GPS) 表面结构 轮廓法 表面粗糙度参数及其数值 | F11: 160
B12: 11 | C12: GB/T 1184-1996 | D12: 形状和位置公差未注公差值 | F12: 161
B13: 12 | C13: GB/T 1220-2007 | D13: 不锈钢棒 | F13: 150
... B42: 42 | C42: GB/T 29463.2-2012 | D42: 管壳式热交换器用垫片第2部分：缠绕式垫片 | F42: 255
B43: 43 | C43: GB/T 29463.3-2012 | D43: 管壳式热交换器用垫片第3部分：非金属软垫片
B44: 44 | C44: GB/T 29465-2012 | D44: 浮头式热交换器用外头盖侧法兰
B45: 45 | C45: GB/T 30579-2014 | D45: 承压设备损伤模式识别
B46: 46 | C46: GB/T 3077-2015 | D46: 合金结构钢
B47: 47 | C47: GB/T 3274-2017 | D47: 碳素结构钢和低合金结构钢热轧钢板和钢带
B48: 48 | C48: GB/T 713.2-2023 | D48: 承压设备用钢板和钢带：第2部 分规定温度性能的非合金钢和合金钢
B49: 49 | C49: GB/T 713.3-2023 | D49: 承压设备用钢板和钢带：第3部 规定低温性能的低合金钢
B50: 50 | C50: GB/T 3625-2007 | D50: 换热器及冷凝器用钛及钛合金管
B51: 51 | C51: GB/T 50128-2014 | D51: 立式圆筒形钢制焊接储罐施工规范
B52: 52 | C52: GB/T 50341-2014 | D52: 立式圆筒形钢制焊接油罐设计规范
B53: 53 | C53: GB/T 50938-2013 | D53: 石油化工钢制低温储罐技术规范
B54: 54 | C54: GB/T 51094-2015 | D54: 工业企业湿式气柜技术规范
... B252: 255 | C252: SH/T 3119-2016 | D252: 石油化工钢制套管换热器技术规范

Sheet Standard (old1)
B1: 251 | D1: 注：ID号码不能更改了 | F1: 设计制造与检验标准
B2: 1 | C2: GB 4053.1-2009 | D2: 固定式钢梯及平台安全要求 第1部分 钢直梯 | F2: 231
B3: 2 | C3: GB 4053.2-2009 | D3: 固定式钢梯及平台安全要求 第2部分 钢斜梯 | F3: 21
B4: 3 | C4: GB 4053.3-2009 | D4: 固定式钢梯及平台安全要求 第3部分：工业防护栏杆及钢平台 | F4: 27
B5: 4 | C5: GB 50009-2012 | D5: 建筑结构荷载规范 | F5: 209
B6: 5 | C6: GB 50011-2010 | D6: 建筑抗震设计规范 | F6: 210
B7: 6 | C7: GB 50017-2003 | D7: 钢结构设计规范 | F7: 14
B8: 7 | C8: GB 50094-2010 | D8: 球形储罐施工规范 | F8: 148
B9: 8 | C9: GB 6178-1986 | D9: 1型六角开槽螺母--A和B级 | F9: 51
B10: 9 | C10: GB 6181-1986 | D10: 六角开槽薄螺母--A和B级 | F10: 52
B11: 10 | C11: GB/T 1031-2009 | D11: 产品几何技术规范(GPS) 表面结构 轮廓法 表面粗糙度参数及其数值 | F11: 160
B12: 11 | C12: GB/T 1184-1996 | D12: 形状和位置公差未注公差值 | F12: 161
B13: 12 | C13: GB/T 1220-2007 | D13: 不锈钢棒 | F13: 150
... B42: 42 | C42: GB/T 29463.2-2012 | D42: 管壳式热交换器用垫片第2部分：缠绕式垫片 | F42: 255
B43: 43 | C43: GB/T 29463.3-2012 | D43: 管壳式热交换器用垫片第3部分：非金属软垫片
B44: 44 | C44: GB/T 29465-2012 | D44: 浮头式热交换器用外头盖侧法兰
B45: 45 | C45: GB/T 30579-2014 | D45: 承压设备损伤模式识别
B46: 46 | C46: GB/T 3077-2015 | D46: 合金结构钢
B47: 47 | C47: GB/T 3274-2017 | D47: 碳素结构钢和低合金结构钢热轧钢板和钢带
B48: 48 | C48: GB/T 713.2-2023 | D48: 承压设备用钢板和钢带：第2部 分规定温度性能的非合金钢和合金钢
B49: 49 | C49: GB/T 713.3-2023 | D49: 承压设备用钢板和钢带：第3部 规定低温性能的低合金钢
B50: 50 | C50: GB/T 3625-2007 | D50: 换热器及冷凝器用钛及钛合金管
B51: 51 | C51: GB/T 50128-2014 | D51: 立式圆筒形钢制焊接储罐施工规范
B52: 52 | C52: GB/T 50341-2014 | D52: 立式圆筒形钢制焊接油罐设计规范
B53: 53 | C53: GB/T 50938-2013 | D53: 石油化工钢制低温储罐技术规范
B54: 54 | C54: GB/T 51094-2015 | D54: 工业企业湿式气柜技术规范
... B252: 255 | C252: SH/T 3119-2016 | D252: 石油化工钢制套管换热器技术规范

Sheet 记事本
B2: 8 | E2: 12
B3: 序号 | C3: 介质特性 | E3: 序号 | F3: 容器类别
B4: 1 | C4: 无 | E4: 1 | F4: --
B5: 2 | C5: 易爆 | E5: 2 | F5: Ⅰ/D1
B6: 3 | C6: 中度危害 | E6: 3 | F6: Ⅱ/D2
B7: 4 | C7: 高度危害 | E7: 4 | F7: Ⅲ/A1
B8: 5 | C8: 极度危害 | E8: 5 | F8: Ⅲ/A2
B9: 6 | C9: 易爆、中度危害 | E9: 6 | F9: Ⅲ/A3
B10: 7 | C10: 易爆、高度危害 | E10: 7 | F10: Ⅱ/A3
B11: 8 | C11: 易爆、极度危害 | E11: 8 | F11: Ⅰ/A3
E12: 9 | F12: Ⅱ/A1
E13: 10 | F13: Ⅰ/SAD
E14: 11 | F14: Ⅱ/SAD
E15: 12 | F15: Ⅲ/SAD
