Workbook

Sheet PipeN
A1: 99 | B1: 5
A2: Type | B2: DN | C2: NPS | D2: Do | E2: NPS_1
A3: Ia系列 | B3: 6 | C3: 1/8" | D3: 10.2 | E3: =1/8 -> 0.125
A4: Ia系列 | B4: 8 | C4: 1/4" | D4: 13.5 | E4: =1/4 -> 0.25
A5: Ia系列 | B5: 10 | C5: 3/8" | D5: 17.2 | E5: =3/8 -> 0.375
A6: Ia系列 | B6: 15 | C6: 1/2" | D6: 21.3 | E6: =1/2 -> 0.5
A7: Ia系列 | B7: 20 | C7: 3/4" | D7: 26.9 | E7: =3/4 -> 0.75
A8: Ia系列 | B8: 25 | C8: 1" | D8: 33.7 | E8: 1
A9: Ia系列 | B9: 32 | C9: 1 1/4" | D9: 42.4 | E9: =1+1/4 -> 1.25
A10: Ia系列 | B10: 40 | C10: 1 1/2" | D10: 48.3 | E10: =1+1/2 -> 1.5
A11: Ia系列 | B11: 50 | C11: 2" | D11: 60.3 | E11: =2 -> 2
A12: Ia系列 | B12: 65 | C12: 2 1/2" | D12: 76.1 | E12: =2+1/2 -> 2.5
A13: Ia系列 | B13: 80 | C13: 3" | D13: 88.9 | E13: 3
A14: Ia系列 | B14: 100 | C14: 4" | D14: 114.3 | E14: 4
A15: Ia系列 | B15: 125 | C15: 5" | D15: 139.7 | E15: 5
A16: Ia系列 | B16: 150 | C16: 6" | D16: 168.3 | E16: 6
A17: Ia系列 | B17: 200 | C17: 8" | D17: 219.1 | E17: 8
A18: Ia系列 | B18: 250 | C18: 10" | D18: 273 | E18: 10
A19: Ia系列 | B19: 300 | C19: 12" | D19: 323.9 | E19: 12
A20: Ia系列 | B20: 350 | C20: 14" | D20: 355.6 | E20: 14
A21: Ia系列 | B21: 400 | C21: 16" | D21: 406.4 | E21: 16
A22: Ia系列 | B22: 450 | C22: 18" | D22: 457 | E22: 18
A23: Ia系列 | B23: 500 | C23: 20" | D23: 508 | E23: 20
A24: Ia系列 | B24: 550 | C24: 22" | D24: 559 | E24: 22
... A48: Ia系列 | B48: 2000 | C48: 80" | D48: 2032 | E48: 80
A49: Ib系列 | B49: 6 | C49: 1/8" | D49: 10 | E49: =1/8 -> 0.125
A50: Ib系列 | B50: 8 | C50: 1/4" | D50: 14 | E50: =1/4 -> 0.25
A51: Ib系列 | B51: 10 | C51: 3/8" | D51: 17 | E51: =3/8 -> 0.375
A52: Ib系列 | B52: 15 | C52: 1/2" | D52: 22 | E52: =1/2 -> 0.5
A53: Ib系列 | B53: 20 | C53: 3/4" | D53: 27 | E53: =3/4 -> 0.75
A54: Ib系列 | B54: 25 | C54: 1" | D54: 34 | E54: 1
A55: Ib系列 | B55: 32 | C55: 1 1/4" | D55: 42 | E55: =1+1/4 -> 1.25
A56: Ib系列 | B56: 40 | C56: 1 1/2" | D56: 48 | E56: =1+1/2 -> 1.5
A57: Ib系列 | B57: 50 | C57: 2" | D57: 60 | E57: =2 -> 2
A58: Ib系列 | B58: 65 | C58: 2 1/2" | D58: 76 | E58: =2+1/2 -> 2.5
A59: Ib系列 | B59: 80 | C59: 3" | D59: 89 | E59: 3
A60: Ib系列 | B60: 100 | C60: 4" | D60: 114 | E60: 4
A61: Ib系列 | B61: 125 | C61: 5" | D61: 140 | E61: 5
A62: Ib系列 | B62: 150 | C62: 6" | D62: 168 | E62: 6
A63: Ib系列 | B63: 200 | C63: 8" | D63: 219 | E63: 8
...

Sheet Pipe
A1: 1362 | B1: 5
A2: Standard | B2: Type | C2: DN | D2: Thk_Sch | E2: Thk
A3: HG/T 20553-2011 | B3: Ia系列 | C3: 6 | D3: Sch.10S | E3: 1.2
A4: HG/T 20553-2011 | B4: Ia系列 | C4: 6 | D4: Sch.10 | E4: 1.2
A5: HG/T 20553-2011 | B5: Ia系列 | C5: 6 | D5: Sch.30 | E5: 1.6
A6: HG/T 20553-2011 | B6: Ia系列 | C6: 6 | D6: Sch.40S | E6: 1.8
A7: HG/T 20553-2011 | B7: Ia系列 | C7: 6 | D7: Sch.40 | E7: 1.8
A8: HG/T 20553-2011 | B8: Ia系列 | C8: 6 | D8: Sch.80S | E8: 2.3
A9: HG/T 20553-2011 | B9: Ia系列 | C9: 6 | D9: Sch.80 | E9: 2.3 | H9: 管件标准
A10: HG/T 20553-2011 | B10: Ia系列 | C10: 8 | D10: Sch.10S | E10: 1.6 | H10: 类型
A11: HG/T 20553-2011 | B11: Ia系列 | C11: 8 | D11: Sch.10 | E11: 1.6 | H11: 管子系列
A12: HG/T 20553-2011 | B12: Ia系列 | C12: 8 | D12: Sch.30 | E12: 1.8 | H12: 公称直径1
A13: HG/T 20553-2011 | B13: Ia系列 | C13: 8 | D13: Sch.40S | E13: 2.3 | H13: 公称直径2
A14: HG/T 20553-2011 | B14: Ia系列 | C14: 8 | D14: Sch.40 | E14: 2.3 | H14: 壁厚
A15: HG/T 20553-2011 | B15: Ia系列 | C15: 8 | D15: Sch.80S | E15: 2.9
A16: HG/T 20553-2011 | B16: Ia系列 | C16: 8 | D16: Sch.80 | E16: 2.9
A17: HG/T 20553-2011 | B17: Ia系列 | C17: 10 | D17: Sch.10S | E17: 1.6
A18: HG/T 20553-2011 | B18: Ia系列 | C18: 10 | D18: Sch.10 | E18: 1.6
A19: HG/T 20553-2011 | B19: Ia系列 | C19: 10 | D19: Sch.30 | E19: 1.8
A20: HG/T 20553-2011 | B20: Ia系列 | C20: 10 | D20: Sch.40S | E20: 2.3
A21: HG/T 20553-2011 | B21: Ia系列 | C21: 10 | D21: Sch.40 | E21: 2.3
A22: HG/T 20553-2011 | B22: Ia系列 | C22: 10 | D22: Sch.80S | E22: 3.2
A23: HG/T 20553-2011 | B23: Ia系列 | C23: 10 | D23: Sch.80 | E23: 3.2
A24: HG/T 20553-2011 | B24: Ia系列 | C24: 15 | D24: Sch.5S | E24: 1.6
A25: HG/T 20553-2011 | B25: Ia系列 | C25: 15 | D25: Sch.5 | E25: 1.6
A26: HG/T 20553-2011 | B26: Ia系列 | C26: 15 | D26: Sch.10S | E26: 2
... A1364: HG/T 20553-2011 | B1364: II系列 | C1364: 2000 | D1364: 16mm | E1364: 16

Sheet PipeC
A1: 80 | B1: 7
A2: Standard | B2: Type | C2: DN | D2: NPS | E2: DoA | F2: DoB | G2: L1 | I2: 11 | J2: HG/T 20553-2011
A3: 04-1484 | B3: Ⅰ型/Ⅲ型 | C3: 10 | D3: =VLOOKUP(C3,PipeN!$B$3:$D$48,2,FALSE) -> 3/8" | E3: =VLOOKUP(C3,PipeN!$B$3:$D$48,3,FALSE) -> 17.2 | G3: 10 | I3: 12 | J3: 04-1484
A4: 04-1484 | B4: Ⅰ型/Ⅲ型 | C4: 15 | D4: =VLOOKUP(C4,PipeN!$B$3:$D$48,2,FALSE) -> 1/2" | E4: =VLOOKUP(C4,PipeN!$B$3:$D$48,3,FALSE) -> 21.3 | G4: 10 | I4: 13 | J4: 04-70995
A5: 04-1484 | B5: Ⅰ型/Ⅲ型 | C5: 20 | D5: =VLOOKUP(C5,PipeN!$B$3:$D$48,2,FALSE) -> 3/4" | E5: =VLOOKUP(C5,PipeN!$B$3:$D$48,3,FALSE) -> 26.9 | G5: 10 | I5: 14 | J5: GB/T12459—2017
A6: 04-1484 | B6: Ⅰ型/Ⅲ型 | C6: 25 | D6: =VLOOKUP(C6,PipeN!$B$3:$D$48,2,FALSE) -> 1" | E6: =VLOOKUP(C6,PipeN!$B$3:$D$48,3,FALSE) -> 33.7 | G6: 14 | L6: 管件标准 | M6: 04-70995 | N6: 0
A7: 04-1484 | B7: Ⅰ型/Ⅲ型 | C7: 32 | D7: =VLOOKUP(C7,PipeN!$B$3:$D$48,2,FALSE) -> 1 1/4" | E7: =VLOOKUP(C7,PipeN!$B$3:$D$48,3,FALSE) -> 42.4 | G7: 14 | I7: 21 | J7: Ⅰ型 | L7: 类型 | M7: 翻边短节(长型) | N7: 1
A8: 04-1484 | B8: Ⅰ型/Ⅲ型 | C8: 40 | D8: =VLOOKUP(C8,PipeN!$B$3:$D$48,2,FALSE) -> 1 1/2" | E8: =VLOOKUP(C8,PipeN!$B$3:$D$48,3,FALSE) -> 48.3 | G8: 16 | I8: 22 | J8: Ⅱ型 | L8: 管子系列 | M8: Ib系列 | N8: 2
A9: 04-1484 | B9: Ⅰ型/Ⅲ型 | C9: 50 | D9: =VLOOKUP(C9,PipeN!$B$3:$D$48,2,FALSE) -> 2" | E9: =VLOOKUP(C9,PipeN!$B$3:$D$48,3,FALSE) -> 60.3 | G9: 16 | I9: 23 | J9: Ⅲ型 | L9: 公称直径1 | M9: 250 | N9: 3
A10: 04-1484 | B10: Ⅰ型/Ⅲ型 | C10: 65 | D10: =VLOOKUP(C10,PipeN!$B$3:$D$48,2,FALSE) -> 2 1/2" | E10: =VLOOKUP(C10,PipeN!$B$3:$D$48,3,FALSE) -> 76.1 | G10: 16 | I10: 24 | J10: Ⅳ型 | L10: 公称直径2 | M10: 500 | N10: 4
A11: 04-1484 | B11: Ⅰ型/Ⅲ型 | C11: 80 | D11: =VLOOKUP(C11,PipeN!$B$3:$D$48,2,FALSE) -> 3" | E11: =VLOOKUP(C11,PipeN!$B$3:$D$48,3,FALSE) -> 88.9 | G11: 16 | L11: 壁厚 | M11: Sch.10 | N11: 5
A12: 04-1484 | B12: Ⅰ型/Ⅲ型 | C12: 100 | D12: =VLOOKUP(C12,PipeN!$B$3:$D$48,2,FALSE) -> 4" | E12: =VLOOKUP(C12,PipeN!$B$3:$D$48,3,FALSE) -> 114.3 | G12: 20 | I12: 31 | J12: Ia系列 | L12: 焊接管 | M12: 无缝 | N12: 6
A13: 04-1484 | B13: Ⅰ型/Ⅲ型 | C13: 125 | D13: =VLOOKUP(C13,PipeN!$B$3:$D$48,2,FALSE) -> 5" | E13: =VLOOKUP(C13,PipeN!$B$3:$D$48,3,FALSE) -> 139.7 | G13: 20 | I13: 32 | J13: Ib系列
A14: 04-1484 | B14: Ⅰ型/Ⅲ型 | C14: 150 | D14: =VLOOKUP(C14,PipeN!$B$3:$D$48,2,FALSE) -> 6" | E14: =VLOOKUP(C14,PipeN!$B$3:$D$48,3,FALSE) -> 168.3 | G14: 20 | I14: 33 | J14: II系列
A15: 04-1484 | B15: Ⅰ型/Ⅲ型 | C15: 200 | D15: =VLOOKUP(C15,PipeN!$B$3:$D$48,2,FALSE) -> 8" | E15: =VLOOKUP(C15,PipeN!$B$3:$D$48,3,FALSE) -> 219.1 | G15: 20
A16: 04-1484 | B16: Ⅰ型/Ⅲ型 | C16: 250 | D16: =VLOOKUP(C16,PipeN!$B$3:$D$48,2,FALSE) -> 10" | E16: =VLOOKUP(C16,PipeN!$B$3:$D$48,3,FALSE) -> 273 | G16: 24 | I16: 51 | J16: 长半径 45°弯头
A17: 04-1484 | B17: Ⅰ型/Ⅲ型 | C17: 300 | D17: =VLOOKUP(C17,PipeN!$B$3:$D$48,2,FALSE) -> 12" | E17: =VLOOKUP(C17,PipeN!$B$3:$D$48,3,FALSE) -> 323.9 | G17: 24 | I17: 52 | J17: 长半径 90°弯头
A18: 04-1484 | B18: Ⅰ型/Ⅲ型 | C18: 350 | D18: =VLOOKUP(C18,PipeN!$B$3:$D$48,2,FALSE) -> 14" | E18: =VLOOKUP(C18,PipeN!$B$3:$D$48,3,FALSE) -> 355.6 | G18: 24 | I18: 53 | J18: 长半径 180°弯头
A19: 04-1484 | B19: Ⅰ型/Ⅲ型 | C19: 400 | D19: =VLOOKUP(C19,PipeN!$B$3:$D$48,2,FALSE) -> 16" | E19: =VLOOKUP(C19,PipeN!$B$3:$D$48,3,FALSE) -> 406.4 | G19: 24 | I19: 54 | J19: 短半径 90°弯头
A20: 04-1484 | B20: Ⅰ型/Ⅲ型 | C20: 450 | D20: =VLOOKUP(C20,PipeN!$B$3:$D$48,2,FALSE) -> 18" | E20: =VLOOKUP(C20,PipeN!$B$3:$D$48,3,FALSE) -> 457 | G20: 24 | I20: 55 | J20: 短半径 180°弯头
A21: 04-1484 | B21: Ⅰ型/Ⅲ型 | C21: 500 | D21: =VLOOKUP(C21,PipeN!$B$3:$D$48,2,FALSE) -> 20" | E21: =VLOOKUP(C21,PipeN!$B$3:$D$48,3,FALSE) -> 508 | G21: 24 | I21: 56 | J21: 3D 45°弯头
A22: 04-1484 | B22: Ⅰ型/Ⅲ型 | C22: 600 | D22: =VLOOKUP(C22,PipeN!$B$3:$D$48,2,FALSE) -> 24" | E22: =VLOOKUP(C22,PipeN!$B$3:$D$48,3,FALSE) -> 610 | G22: 24 | I22: 57 | J22: 3D 90°弯头
A23: 04-1484 | B23: Ⅱ型/Ⅳ型 | C23: 10 | D23: =VLOOKUP(C23,PipeN!$B$3:$D$48,2,FALSE) -> 3/8" | E23: =VLOOKUP(C23,PipeN!$B$3:$D$48,3,FALSE) -> 17.2 | G23: 40 | I23: 58 | J23: 等径三通
A24: 04-1484 | B24: Ⅱ型/Ⅳ型 | C24: 15 | D24: =VLOOKUP(C24,PipeN!$B$3:$D$48,2,FALSE) -> 1/2" | E24: =VLOOKUP(C24,PipeN!$B$3:$D$48,3,FALSE) -> 21.3 | G24: 40 | I24: 59 | J24: 等径四通
A25: 04-1484 | B25: Ⅱ型/Ⅳ型 | C25: 20 | D25: =VLOOKUP(C25,PipeN!$B$3:$D$48,2,FALSE) -> 3/4" | E25: =VLOOKUP(C25,PipeN!$B$3:$D$48,3,FALSE) -> 26.9 | G25: 45 | I25: 60 | J25: 管帽
A26: 04-1484 | B26: Ⅱ型/Ⅳ型 | C26: 25 | D26: =VLOOKUP(C26,PipeN!$B$3:$D$48,2,FALSE) -> 1" | E26: =VLOOKUP(C26,PipeN!$B$3:$D$48,3,FALSE) -> 33.7 | G26: 45 | I26: 61 | J26: 翻边短节(长型)
A27: 04-1484 | B27: Ⅱ型/Ⅳ型 | C27: 32 | D27: =VLOOKUP(C27,PipeN!$B$3:$D$48,2,FALSE) -> 1 1/4" | E27: =VLOOKUP(C27,PipeN!$B$3:$D$48,3,FALSE) -> 42.4 | G27: 45 | I27: 62 | J27: 翻边短节(短型)
... A30: 04-1484 | B30: Ⅱ型/Ⅳ型 | C30: 65 | D30: =VLOOKUP(C30,PipeN!$B$3:$D$48,2,FALSE) -> 2 1/2" | E30: =VLOOKUP(C30,PipeN!$B$3:$D$48,3,FALSE) -> 76.1 | G30: 55 | I30: 65 | J30: 异径四通
A31: 04-1484 | B31: Ⅱ型/Ⅳ型 | C31: 80 | D31: =VLOOKUP(C31,PipeN!$B$3:$D$48,2,FALSE) -> 3" | E31: =VLOOKUP(C31,PipeN!$B$3:$D$48,3,FALSE) -> 88.9 | G31: 60
A32: 04-1484 | B32: Ⅱ型/Ⅳ型 | C32: 100 | D32: =VLOOKUP(C32,PipeN!$B$3:$D$48,2,FALSE) -> 4" | E32: =VLOOKUP(C32,PipeN!$B$3:$D$48,3,FALSE) -> 114.3 | G32: 65 | I32: 81 | J32: 焊接
A33: 04-1484 | B33: Ⅱ型/Ⅳ型 | C33: 125 | D33: =VLOOKUP(C33,PipeN!$B$3:$D$48,2,FALSE) -> 5" | E33: =VLOOKUP(C33,PipeN!$B$3:$D$48,3,FALSE) -> 139.7 | G33: 70 | I33: 82 | J33: 无缝
A34: 04-1484 | B34: Ⅱ型/Ⅳ型 | C34: 150 | D34: =VLOOKUP(C34,PipeN!$B$3:$D$48,2,FALSE) -> 6" | E34: =VLOOKUP(C34,PipeN!$B$3:$D$48,3,FALSE) -> 168.3 | G34: 70
A35: 04-1484 | B35: Ⅱ型/Ⅳ型 | C35: 200 | D35: =VLOOKUP(C35,PipeN!$B$3:$D$48,2,FALSE) -> 8" | E35: =VLOOKUP(C35,PipeN!$B$3:$D$48,3,FALSE) -> 219.1 | G35: 80
A36: 04-1484 | B36: Ⅱ型/Ⅳ型 | C36: 250 | D36: =VLOOKUP(C36,PipeN!$B$3:$D$48,2,FALSE) -> 10" | E36: =VLOOKUP(C36,PipeN!$B$3:$D$48,3,FALSE) -> 273 | G36: 85
A37: 04-1484 | B37: Ⅱ型/Ⅳ型 | C37: 300 | D37: =VLOOKUP(C37,PipeN!$B$3:$D$48,2,FALSE) -> 12" | E37: =VLOOKUP(C37,PipeN!$B$3:$D$48,3,FALSE) -> 323.9 | G37: 90
A38: 04-1484 | B38: Ⅱ型/Ⅳ型 | C38: 350 | D38: =VLOOKUP(C38,PipeN!$B$3:$D$48,2,FALSE) -> 14" | E38: =VLOOKUP(C38,PipeN!$B$3:$D$48,3,FALSE) -> 355.6 | G38: 100
A39: 04-1484 | B39: Ⅱ型/Ⅳ型 | C39: 400 | D39: =VLOOKUP(C39,PipeN!$B$3:$D$48,2,FALSE) -> 16" | E39: =VLOOKUP(C39,PipeN!$B$3:$D$48,3,FALSE) -> 406.4 | G39: 110
A40: 04-1484 | B40: Ⅱ型/Ⅳ型 | C40: 450 | D40: =VLOOKUP(C40,PipeN!$B$3:$D$48,2,FALSE) -> 18" | E40: =VLOOKUP(C40,PipeN!$B$3:$D$48,3,FALSE) -> 457 | G40: 120
A41: 04-1484 | B41: Ⅱ型/Ⅳ型 | C41: 500 | D41: =VLOOKUP(C41,PipeN!$B$3:$D$48,2,FALSE) -> 20" | E41: =VLOOKUP(C41,PipeN!$B$3:$D$48,3,FALSE) -> 508 | G41: 125
A42: 04-1484 | B42: Ⅱ型/Ⅳ型 | C42: 600 | D42: =VLOOKUP(C42,PipeN!$B$3:$D$48,2,FALSE) -> 24" | E42: =VLOOKUP(C42,PipeN!$B$3:$D$48,3,FALSE) -> 610 | G42: 130
...

Sheet PipeT
A1: 35 | B1: 20 | C1: GB/T12459—2017 | E1: 长半径 | H1: 短半径 | J1: 3D | L1: 等径三通四通 | N1: 管帽 | O1: 翻边短节
C2: Do | E2: 90°弯头 | F2: 45°弯头 | G2: 180°弯头 | H2: 90°弯头 | I2: 180°弯头 | J2: 90°弯头 | K2: 45°弯头 | L2: 主管 | M2: 支管 | N2: 高度 | O2: 短节外径 | Q2: 短节长度 | S2: 圆角半径 | T2: 搭边外径
A3: DN | B3: NPS | C3: I系列 | D3: II系列 | E3: A | F3: B | G3: O | H3: A | I3: O | J3: A | K3: B | L3: C | M3: M | N3: E | O3: Dmax | P3: Dmin | Q3: F1 | R3: F2 | S3: R | T3: G
A4: 15 | B4: =VLOOKUP(A4,PipeN!$B$3:$D$48,2,FALSE) -> 1/2" | C4: =VLOOKUP(A4,PipeN!$B$3:$D$48,3,FALSE) -> 21.3 | D4: =VLOOKUP(A4,PipeN!$B$72:$D$101,3,FALSE) -> 18 | E4: 38 | F4: 16 | G4: 76 | L4: 25 | M4: 25 | N4: 25 | O4: 22.8 | P4: 20.5 | Q4: 76 | R4: 51 | S4: 3 | T4: 35
A5: 20 | B5: =VLOOKUP(A5,PipeN!$B$3:$D$48,2,FALSE) -> 3/4" | C5: =VLOOKUP(A5,PipeN!$B$3:$D$48,3,FALSE) -> 26.9 | D5: =VLOOKUP(A5,PipeN!$B$72:$D$101,3,FALSE) -> 25 | E5: 38 | F5: 19 | G5: 76 | J5: 57 | K5: 24 | L5: 29 | M5: 29 | N5: 25 | O5: 28.1 | P5: 25.9 | Q5: 76 | R5: 51 | S5: 3 | T5: 43
A6: 25 | B6: =VLOOKUP(A6,PipeN!$B$3:$D$48,2,FALSE) -> 1" | C6: =VLOOKUP(A6,PipeN!$B$3:$D$48,3,FALSE) -> 33.7 | D6: =VLOOKUP(A6,PipeN!$B$72:$D$101,3,FALSE) -> 32 | E6: 38 | F6: 22 | G6: 76 | H6: 25 | I6: 61 | J6: 76 | K6: 31 | L6: 38 | M6: 38 | N6: 38 | O6: 35 | P6: 32.6 | Q6: 102 | R6: 51 | S6: 3 | T6: 51
A7: 32 | B7: =VLOOKUP(A7,PipeN!$B$3:$D$48,2,FALSE) -> 1 1/4" | C7: =VLOOKUP(A7,PipeN!$B$3:$D$48,3,FALSE) -> 42.4 | D7: =VLOOKUP(A7,PipeN!$B$72:$D$101,3,FALSE) -> 38 | E7: 48 | F7: 25 | G7: 95 | H7: 32 | I7: 64 | J7: 95 | K7: 39 | L7: 48 | M7: 48 | N7: 68 | O7: 43.6 | P7: 41.4 | Q7: 102 | R7: 51 | S7: 5 | T7: 64
A8: 40 | B8: =VLOOKUP(A8,PipeN!$B$3:$D$48,2,FALSE) -> 1 1/2" | C8: =VLOOKUP(A8,PipeN!$B$3:$D$48,3,FALSE) -> 48.3 | D8: =VLOOKUP(A8,PipeN!$B$72:$D$101,3,FALSE) -> 45 | E8: 57 | F8: 29 | G8: 114 | H8: 38 | I8: 75 | J8: 114 | K8: 47 | L8: 57 | M8: 57 | N8: 38 | O8: 49.9 | P8: 47.5 | Q8: 102 | R8: 51 | S8: 6 | T8: 73
A9: 50 | B9: =VLOOKUP(A9,PipeN!$B$3:$D$48,2,FALSE) -> 2" | C9: =VLOOKUP(A9,PipeN!$B$3:$D$48,3,FALSE) -> 60.3 | D9: =VLOOKUP(A9,PipeN!$B$72:$D$101,3,FALSE) -> 57 | E9: 76 | F9: 35 | G9: 152 | H9: 51 | I9: 102 | J9: 152 | K9: 63 | L9: 64 | M9: 64 | N9: 38 | O9: 62.4 | P9: 59.5 | Q9: 152 | R9: 64 | S9: 8 | T9: 92
A10: 65 | B10: =VLOOKUP(A10,PipeN!$B$3:$D$48,2,FALSE) -> 2 1/2" | C10: =VLOOKUP(A10,PipeN!$B$3:$D$48,3,FALSE) -> 76.1 | D10: =VLOOKUP(A10,PipeN!$B$72:$D$101,3,FALSE) -> 76 | E10: 95 | F10: 44 | G10: 190 | H10: 54 | I10: 127 | J10: 190 | K10: 79 | L10: 76 | M10: 76 | N10: 38 | O10: 75.3 | P10: 72.2 | Q10: 152 | R10: 64 | S10: 8 | T10: 105
A11: 80 | B11: =VLOOKUP(A11,PipeN!$B$3:$D$48,2,FALSE) -> 3" | C11: =VLOOKUP(A11,PipeN!$B$3:$D$48,3,FALSE) -> 88.9 | D11: =VLOOKUP(A11,PipeN!$B$72:$D$101,3,FALSE) -> 89 | E11: 114 | F11: 51 | G11: 229 | H11: 76 | I11: 152 | J11: 229 | K11: 95 | L11: 86 | M11: 86 | N11: 51 | O11: 91.3 | P11: 88.1 | Q11: 152 | R11: 64 | S11: 10 | T11: 127
A12: 100 | B12: =VLOOKUP(A12,PipeN!$B$3:$D$48,2,FALSE) -> 4" | C12: =VLOOKUP(A12,PipeN!$B$3:$D$48,3,FALSE) -> 114.3 | D12: =VLOOKUP(A12,PipeN!$B$72:$D$101,3,FALSE) -> 108 | E12: 152 | F12: 64 | G12: 305 | H12: 102 | I12: 203 | J12: 305 | K12: 127 | L12: 105 | M12: 105 | N12: 64 | O12: 116.7 | P12: 113.5 | Q12: 152 | R12: 76 | S12: 11 | T12: 157
A13: 125 | B13: =VLOOKUP(A13,PipeN!$B$3:$D$48,2,FALSE) -> 5" | C13: =VLOOKUP(A13,PipeN!$B$3:$D$48,3,FALSE) -> 139.7 | D13: =VLOOKUP(A13,PipeN!$B$72:$D$101,3,FALSE) -> 133 | E13: 190 | F13: 79 | G13: 381 | H13: 127 | I13: 254 | J13: 381 | K13: 157 | L13: 124 | M13: 124 | N13: 76 | O13: 144.3 | P13: 140.5 | Q13: 203 | R13: 76 | S13: 11 | T13: 186
A14: 150 | B14: =VLOOKUP(A14,PipeN!$B$3:$D$48,2,FALSE) -> 6" | C14: =VLOOKUP(A14,PipeN!$B$3:$D$48,3,FALSE) -> 168.3 | D14: =VLOOKUP(A14,PipeN!$B$72:$D$101,3,FALSE) -> 159 | E14: 229 | F14: 95 | G14: 457 | H14: 152 | I14: 305 | J14: 457 | K14: 189 | L14: 143 | M14: 143 | N14: 89 | O14: 171.3 | P14: 167.5 | Q14: 203 | R14: 89 | S14: 13 | T14: 216
A15: 200 | B15: =VLOOKUP(A15,PipeN!$B$3:$D$48,2,FALSE) -> 8" | C15: =VLOOKUP(A15,PipeN!$B$3:$D$48,3,FALSE) -> 219.1 | D15: =VLOOKUP(A15,PipeN!$B$72:$D$101,3,FALSE) -> 219 | E15: 305 | F15: 127 | G15: 610 | H15: 203 | I15: 406 | J15: 610 | K15: 252 | L15: 178 | M15: 178 | N15: 102 | O15: 222.1 | P15: 218.3 | Q15: 203 | R15: 102 | S15: 13 | T15: 270
A16: 250 | B16: =VLOOKUP(A16,PipeN!$B$3:$D$48,2,FALSE) -> 10" | C16: =VLOOKUP(A16,PipeN!$B$3:$D$48,3,FALSE) -> 273 | D16: =VLOOKUP(A16,PipeN!$B$72:$D$101,3,FALSE) -> 273 | E16: 381 | F16: 159 | G16: 762 | H16: 254 | I16: 508 | J16: 762 | K16: 316 | L16: 216 | M16: 216 | N16: 127 | O16: 277.2 | P16: 272.3 | Q16: 254 | R16: 127 | S16: 13 | T16: 324
A17: 300 | B17: =VLOOKUP(A17,PipeN!$B$3:$D$48,2,FALSE) -> 12" | C17: =VLOOKUP(A17,PipeN!$B$3:$D$48,3,FALSE) -> 323.9 | D17: =VLOOKUP(A17,PipeN!$B$72:$D$101,3,FALSE) -> 325 | E17: 457 | F17: 190 | G17: 914 | H17: 305 | I17: 610 | J17: 914 | K17: 378 | L17: 254 | M17: 254 | N17: 152 | O17: 328 | P17: 323.1 | Q17: 254 | R17: 152 | S17: 13 | T17: 381
... A21: 500 | B21: =VLOOKUP(A21,PipeN!$B$3:$D$48,2,FALSE) -> 20" | C21: =VLOOKUP(A21,PipeN!$B$3:$D$48,3,FALSE) -> 508 | D21: =VLOOKUP(A21,PipeN!$B$72:$D$101,3,FALSE) -> 530 | E21: 762 | F21: 318 | G21: 1524 | H21: 508 | I21: 1016 | J21: 1524 | K21: 632 | L21: 381 | M21: 381 | N21: 229 | O21: 514 | P21: 507 | Q21: 305 | R21: 152 | S21: 13 | T21: 584
A22: 550 | B22: =VLOOKUP(A22,PipeN!$B$3:$D$48,2,FALSE) -> 22" | C22: =VLOOKUP(A22,PipeN!$B$3:$D$48,3,FALSE) -> 559 | E22: 838 | F22: 343 | G22: 1676 | H22: 559 | I22: 1118 | J22: 1676 | K22: 694 | L22: 419 | M22: 419 | N22: 254 | O22: 565 | P22: 558 | Q22: 305 | R22: 152 | S22: 13 | T22: 641
A23: 600 | B23: =VLOOKUP(A23,PipeN!$B$3:$D$48,2,FALSE) -> 24" | C23: =VLOOKUP(A23,PipeN!$B$3:$D$48,3,FALSE) -> 610 | D23: =VLOOKUP(A23,PipeN!$B$72:$D$101,3,FALSE) -> 630 | E23: 914 | F23: 381 | G23: 1829 | H23: 610 | I23: 1219 | J23: 1829 | K23: 757 | L23: 432 | M23: 432 | N23: 267 | O23: 616 | P23: 609 | Q23: 305 | R23: 152 | S23: 13 | T23: 692
A24: 650 | B24: =VLOOKUP(A24,PipeN!$B$3:$D$48,2,FALSE) -> 26" | C24: =VLOOKUP(A24,PipeN!$B$3:$D$48,3,FALSE) -> 660 | E24: 991 | F24: 406 | J24: 1981 | K24: 821 | L24: 495 | M24: 495 | N24: 267
A25: 700 | B25: =VLOOKUP(A25,PipeN!$B$3:$D$48,2,FALSE) -> 28" | C25: =VLOOKUP(A25,PipeN!$B$3:$D$48,3,FALSE) -> 711 | D25: =VLOOKUP(A25,PipeN!$B$72:$D$101,3,FALSE) -> 720 | E25: 1067 | F25: 438 | J25: 2134 | K25: 883 | L25: 521 | M25: 521 | N25: 267
A26: 750 | B26: =VLOOKUP(A26,PipeN!$B$3:$D$48,2,FALSE) -> 30" | C26: =VLOOKUP(A26,PipeN!$B$3:$D$48,3,FALSE) -> 762 | E26: 1143 | F26: 470 | J26: 2286 | K26: 947 | L26: 559 | M26: 559 | N26: 267
A27: 800 | B27: =VLOOKUP(A27,PipeN!$B$3:$D$48,2,FALSE) -> 32" | C27: =VLOOKUP(A27,PipeN!$B$3:$D$48,3,FALSE) -> 813 | D27: =VLOOKUP(A27,PipeN!$B$72:$D$101,3,FALSE) -> 820 | E27: 1219 | F27: 502 | J27: 2438 | K27: 1010 | L27: 597 | M27: 597 | N27: 267
A28: 850 | B28: =VLOOKUP(A28,PipeN!$B$3:$D$48,2,FALSE) -> 34" | C28: =VLOOKUP(A28,PipeN!$B$3:$D$48,3,FALSE) -> 864 | E28: 1295 | F28: 533 | J28: 2591 | K28: 1073 | L28: 635 | M28: 635 | N28: 267
A29: 900 | B29: =VLOOKUP(A29,PipeN!$B$3:$D$48,2,FALSE) -> 36" | C29: =VLOOKUP(A29,PipeN!$B$3:$D$48,3,FALSE) -> 914 | E29: 1372 | F29: 565 | J29: 2743 | K29: 1135 | L29: 673 | M29: 673 | N29: 267
A30: 950 | B30: =VLOOKUP(A30,PipeN!$B$3:$D$48,2,FALSE) -> 38" | C30: =VLOOKUP(A30,PipeN!$B$3:$D$48,3,FALSE) -> 955 | E30: 1448 | F30: 600 | J30: 2896 | K30: 1200 | L30: 711 | M30: 711 | N30: 305
A31: 1000 | B31: =VLOOKUP(A31,PipeN!$B$3:$D$48,2,FALSE) -> 40" | C31: =VLOOKUP(A31,PipeN!$B$3:$D$48,3,FALSE) -> 1016 | E31: 1524 | F31: 632 | J31: 3048 | K31: 1264 | L31: 749 | M31: 749 | N31: 305
A32: 1050 | B32: =VLOOKUP(A32,PipeN!$B$3:$D$48,2,FALSE) -> 42" | C32: =VLOOKUP(A32,PipeN!$B$3:$D$48,3,FALSE) -> 1067 | E32: 1600 | F32: 660 | J32: 3200 | K32: 1326 | L32: 762 | M32: 711 | N32: 305
A33: 1100 | B33: =VLOOKUP(A33,PipeN!$B$3:$D$48,2,FALSE) -> 44" | C33: =VLOOKUP(A33,PipeN!$B$3:$D$48,3,FALSE) -> 1118 | E33: 1676 | F33: 695 | J33: 3353 | K33: 1389 | L33: 813 | M33: 762 | N33: 343
A34: 1150 | B34: =VLOOKUP(A34,PipeN!$B$3:$D$48,2,FALSE) -> 46" | C34: =VLOOKUP(A34,PipeN!$B$3:$D$48,3,FALSE) -> 1168 | E34: 1753 | F34: 727 | J34: 3505 | K34: 1453 | L34: 851 | M34: 800 | N34: 343
A35: 1200 | B35: =VLOOKUP(A35,PipeN!$B$3:$D$48,2,FALSE) -> 48" | C35: =VLOOKUP(A35,PipeN!$B$3:$D$48,3,FALSE) -> 1219 | E35: 1829 | F35: 759 | J35: 3658 | K35: 1516 | L35: 889 | M35: 838 | N35: 343
A36: 1300 | B36: =VLOOKUP(A36,PipeN!$B$3:$D$48,2,FALSE) -> 52" | C36: =VLOOKUP(A36,PipeN!$B$3:$D$48,3,FALSE) -> 1321 | E36: 1981 | F36: 821 | J36: 3962 | K36: 1641 | L36: 978 | M36: 908 | N36: 368
A37: 1400 | B37: =VLOOKUP(A37,PipeN!$B$3:$D$48,2,FALSE) -> 56" | C37: =VLOOKUP(A37,PipeN!$B$3:$D$48,3,FALSE) -> 1422 | E37: 2134 | F37: 884 | J37: 4267 | K37: 1768 | L37: 1054 | M37: 978 | N37: 406
A38: 1500 | B38: =VLOOKUP(A38,PipeN!$B$3:$D$48,2,FALSE) -> 60" | C38: =VLOOKUP(A38,PipeN!$B$3:$D$48,3,FALSE) -> 1524 | E38: 2286 | F38: 947 | J38: 4572 | K38: 1894 | L38: 1118 | M38: 1054 | N38: 419

Sheet PipeR
A1: 225 | B1: 11 | D1: GB/T12459—2017 | I1: 长半径异 | J1: 异径三通四通
C2: Do | I2: 90°弯头 | J2: 主管 | K2: 支管
A3: DN1 | B3: NPS | C3: I系列 | D3: II系列 | E3: DN2 | F3: NPS | G3: I系列 | H3: II系列 | I3: A/mm | J3: C | K3: M
A4: 15 | B4: =VLOOKUP(A4,PipeN!$B$3:$D$48,2,FALSE) -> 1/2" | C4: =VLOOKUP(A4,PipeN!$B$3:$D$48,3,FALSE) -> 21.3 | D4: =VLOOKUP(A4,PipeN!$B$72:$D$101,3,FALSE) -> 18 | E4: 10 | F4: =VLOOKUP(E4,PipeN!$B$3:$D$48,2,FALSE) -> 3/8" | G4: =VLOOKUP(E4,PipeN!$B$3:$D$48,3,FALSE) -> 17.2 | H4: =VLOOKUP(E4,PipeN!$B$72:$D$101,3,FALSE) -> 14 | J4: 25 | K4: 25
A5: 15 | B5: =VLOOKUP(A5,PipeN!$B$3:$D$48,2,FALSE) -> 1/2" | C5: =VLOOKUP(A5,PipeN!$B$3:$D$48,3,FALSE) -> 21.3 | E5: 8 | F5: =VLOOKUP(E5,PipeN!$B$3:$D$48,2,FALSE) -> 1/4" | G5: =VLOOKUP(E5,PipeN!$B$3:$D$48,3,FALSE) -> 13.5 | J5: 25 | K5: 25
A6: 20 | B6: =VLOOKUP(A6,PipeN!$B$3:$D$48,2,FALSE) -> 3/4" | C6: =VLOOKUP(A6,PipeN!$B$3:$D$48,3,FALSE) -> 26.9 | D6: =VLOOKUP(A6,PipeN!$B$72:$D$101,3,FALSE) -> 25 | E6: 15 | F6: =VLOOKUP(E6,PipeN!$B$3:$D$48,2,FALSE) -> 1/2" | G6: =VLOOKUP(E6,PipeN!$B$3:$D$48,3,FALSE) -> 21.3 | H6: =VLOOKUP(E6,PipeN!$B$72:$D$101,3,FALSE) -> 18 | J6: 29 | K6: 29
A7: 20 | B7: =VLOOKUP(A7,PipeN!$B$3:$D$48,2,FALSE) -> 3/4" | C7: =VLOOKUP(A7,PipeN!$B$3:$D$48,3,FALSE) -> 26.9 | D7: =VLOOKUP(A7,PipeN!$B$72:$D$101,3,FALSE) -> 25 | E7: 10 | F7: =VLOOKUP(E7,PipeN!$B$3:$D$48,2,FALSE) -> 3/8" | G7: =VLOOKUP(E7,PipeN!$B$3:$D$48,3,FALSE) -> 17.2 | H7: =VLOOKUP(E7,PipeN!$B$72:$D$101,3,FALSE) -> 14 | J7: 29 | K7: 29
A8: 25 | B8: =VLOOKUP(A8,PipeN!$B$3:$D$48,2,FALSE) -> 1" | C8: =VLOOKUP(A8,PipeN!$B$3:$D$48,3,FALSE) -> 33.7 | D8: =VLOOKUP(A8,PipeN!$B$72:$D$101,3,FALSE) -> 32 | E8: 20 | F8: =VLOOKUP(E8,PipeN!$B$3:$D$48,2,FALSE) -> 3/4" | G8: =VLOOKUP(E8,PipeN!$B$3:$D$48,3,FALSE) -> 26.9 | H8: =VLOOKUP(E8,PipeN!$B$72:$D$101,3,FALSE) -> 25 | J8: 38 | K8: 38
A9: 25 | B9: =VLOOKUP(A9,PipeN!$B$3:$D$48,2,FALSE) -> 1" | C9: =VLOOKUP(A9,PipeN!$B$3:$D$48,3,FALSE) -> 33.7 | D9: =VLOOKUP(A9,PipeN!$B$72:$D$101,3,FALSE) -> 32 | E9: 15 | F9: =VLOOKUP(E9,PipeN!$B$3:$D$48,2,FALSE) -> 1/2" | G9: =VLOOKUP(E9,PipeN!$B$3:$D$48,3,FALSE) -> 21.3 | H9: =VLOOKUP(E9,PipeN!$B$72:$D$101,3,FALSE) -> 18 | J9: 38 | K9: 38
A10: 32 | B10: =VLOOKUP(A10,PipeN!$B$3:$D$48,2,FALSE) -> 1 1/4" | C10: =VLOOKUP(A10,PipeN!$B$3:$D$48,3,FALSE) -> 42.4 | D10: =VLOOKUP(A10,PipeN!$B$72:$D$101,3,FALSE) -> 38 | E10: 25 | F10: =VLOOKUP(E10,PipeN!$B$3:$D$48,2,FALSE) -> 1" | G10: =VLOOKUP(E10,PipeN!$B$3:$D$48,3,FALSE) -> 33.7 | H10: =VLOOKUP(E10,PipeN!$B$72:$D$101,3,FALSE) -> 32 | J10: 48 | K10: 48
A11: 32 | B11: =VLOOKUP(A11,PipeN!$B$3:$D$48,2,FALSE) -> 1 1/4" | C11: =VLOOKUP(A11,PipeN!$B$3:$D$48,3,FALSE) -> 42.4 | D11: =VLOOKUP(A11,PipeN!$B$72:$D$101,3,FALSE) -> 38 | E11: 20 | F11: =VLOOKUP(E11,PipeN!$B$3:$D$48,2,FALSE) -> 3/4" | G11: =VLOOKUP(E11,PipeN!$B$3:$D$48,3,FALSE) -> 26.9 | H11: =VLOOKUP(E11,PipeN!$B$72:$D$101,3,FALSE) -> 25 | J11: 48 | K11: 48
A12: 32 | B12: =VLOOKUP(A12,PipeN!$B$3:$D$48,2,FALSE) -> 1 1/4" | C12: =VLOOKUP(A12,PipeN!$B$3:$D$48,3,FALSE) -> 42.4 | D12: =VLOOKUP(A12,PipeN!$B$72:$D$101,3,FALSE) -> 38 | E12: 15 | F12: =VLOOKUP(E12,PipeN!$B$3:$D$48,2,FALSE) -> 1/2" | G12: =VLOOKUP(E12,PipeN!$B$3:$D$48,3,FALSE) -> 21.3 | H12: =VLOOKUP(E12,PipeN!$B$72:$D$101,3,FALSE) -> 18 | J12: 48 | K12: 48
A13: 40 | B13: =VLOOKUP(A13,PipeN!$B$3:$D$48,2,FALSE) -> 1 1/2" | C13: =VLOOKUP(A13,PipeN!$B$3:$D$48,3,FALSE) -> 48.3 | D13: =VLOOKUP(A13,PipeN!$B$72:$D$101,3,FALSE) -> 45 | E13: 32 | F13: =VLOOKUP(E13,PipeN!$B$3:$D$48,2,FALSE) -> 1 1/4" | G13: =VLOOKUP(E13,PipeN!$B$3:$D$48,3,FALSE) -> 42.4 | H13: =VLOOKUP(E13,PipeN!$B$72:$D$101,3,FALSE) -> 38 | J13: 57 | K13: 57
A14: 40 | B14: =VLOOKUP(A14,PipeN!$B$3:$D$48,2,FALSE) -> 1 1/2" | C14: =VLOOKUP(A14,PipeN!$B$3:$D$48,3,FALSE) -> 48.3 | D14: =VLOOKUP(A14,PipeN!$B$72:$D$101,3,FALSE) -> 45 | E14: 25 | F14: =VLOOKUP(E14,PipeN!$B$3:$D$48,2,FALSE) -> 1" | G14: =VLOOKUP(E14,PipeN!$B$3:$D$48,3,FALSE) -> 33.7 | H14: =VLOOKUP(E14,PipeN!$B$72:$D$101,3,FALSE) -> 32 | J14: 57 | K14: 57
A15: 40 | B15: =VLOOKUP(A15,PipeN!$B$3:$D$48,2,FALSE) -> 1 1/2" | C15: =VLOOKUP(A15,PipeN!$B$3:$D$48,3,FALSE) -> 48.3 | D15: =VLOOKUP(A15,PipeN!$B$72:$D$101,3,FALSE) -> 45 | E15: 20 | F15: =VLOOKUP(E15,PipeN!$B$3:$D$48,2,FALSE) -> 3/4" | G15: =VLOOKUP(E15,PipeN!$B$3:$D$48,3,FALSE) -> 26.9 | H15: =VLOOKUP(E15,PipeN!$B$72:$D$101,3,FALSE) -> 25 | J15: 57 | K15: 57
A16: 40 | B16: =VLOOKUP(A16,PipeN!$B$3:$D$48,2,FALSE) -> 1 1/2" | C16: =VLOOKUP(A16,PipeN!$B$3:$D$48,3,FALSE) -> 48.3 | D16: =VLOOKUP(A16,PipeN!$B$72:$D$101,3,FALSE) -> 45 | E16: 15 | F16: =VLOOKUP(E16,PipeN!$B$3:$D$48,2,FALSE) -> 1/2" | G16: =VLOOKUP(E16,PipeN!$B$3:$D$48,3,FALSE) -> 21.3 | H16: =VLOOKUP(E16,PipeN!$B$72:$D$101,3,FALSE) -> 18 | J16: 57 | K16: 57
A17: 50 | B17: =VLOOKUP(A17,PipeN!$B$3:$D$48,2,FALSE) -> 2" | C17: =VLOOKUP(A17,PipeN!$B$3:$D$48,3,FALSE) -> 60.3 | D17: =VLOOKUP(A17,PipeN!$B$72:$D$101,3,FALSE) -> 57 | E17: 40 | F17: =VLOOKUP(E17,PipeN!$B$3:$D$48,2,FALSE) -> 1 1/2" | G17: =VLOOKUP(E17,PipeN!$B$3:$D$48,3,FALSE) -> 48.3 | H17: =VLOOKUP(E17,PipeN!$B$72:$D$101,3,FALSE) -> 45 | I17: 76 | J17: 64 | K17: 60
A18: 50 | B18: =VLOOKUP(A18,PipeN!$B$3:$D$48,2,FALSE) -> 2" | C18: =VLOOKUP(A18,PipeN!$B$3:$D$48,3,FALSE) -> 60.3 | D18: =VLOOKUP(A18,PipeN!$B$72:$D$101,3,FALSE) -> 57 | E18: 32 | F18: =VLOOKUP(E18,PipeN!$B$3:$D$48,2,FALSE) -> 1 1/4" | G18: =VLOOKUP(E18,PipeN!$B$3:$D$48,3,FALSE) -> 42.4 | H18: =VLOOKUP(E18,PipeN!$B$72:$D$101,3,FALSE) -> 38 | I18: 76 | J18: 64 | K18: 57
A19: 50 | B19: =VLOOKUP(A19,PipeN!$B$3:$D$48,2,FALSE) -> 2" | C19: =VLOOKUP(A19,PipeN!$B$3:$D$48,3,FALSE) -> 60.3 | D19: =VLOOKUP(A19,PipeN!$B$72:$D$101,3,FALSE) -> 57 | E19: 25 | F19: =VLOOKUP(E19,PipeN!$B$3:$D$48,2,FALSE) -> 1" | G19: =VLOOKUP(E19,PipeN!$B$3:$D$48,3,FALSE) -> 33.7 | H19: =VLOOKUP(E19,PipeN!$B$72:$D$101,3,FALSE) -> 32 | I19: 76 | J19: 64 | K19: 51
A20: 50 | B20: =VLOOKUP(A20,PipeN!$B$3:$D$48,2,FALSE) -> 2" | C20: =VLOOKUP(A20,PipeN!$B$3:$D$48,3,FALSE) -> 60.3 | D20: =VLOOKUP(A20,PipeN!$B$72:$D$101,3,FALSE) -> 57 | E20: 20 | F20: =VLOOKUP(E20,PipeN!$B$3:$D$48,2,FALSE) -> 3/4" | G20: =VLOOKUP(E20,PipeN!$B$3:$D$48,3,FALSE) -> 26.9 | H20: =VLOOKUP(E20,PipeN!$B$72:$D$101,3,FALSE) -> 25 | J20: 64 | K20: 44
A21: 65 | B21: =VLOOKUP(A21,PipeN!$B$3:$D$48,2,FALSE) -> 2 1/2" | C21: =VLOOKUP(A21,PipeN!$B$3:$D$48,3,FALSE) -> 76.1 | D21: =VLOOKUP(A21,PipeN!$B$72:$D$101,3,FALSE) -> 76 | E21: 50 | F21: =VLOOKUP(E21,PipeN!$B$3:$D$48,2,FALSE) -> 2" | G21: =VLOOKUP(E21,PipeN!$B$3:$D$48,3,FALSE) -> 60.3 | H21: =VLOOKUP(E21,PipeN!$B$72:$D$101,3,FALSE) -> 57 | I21: 95 | J21: 76 | K21: 70
A22: 65 | B22: =VLOOKUP(A22,PipeN!$B$3:$D$48,2,FALSE) -> 2 1/2" | C22: =VLOOKUP(A22,PipeN!$B$3:$D$48,3,FALSE) -> 76.1 | D22: =VLOOKUP(A22,PipeN!$B$72:$D$101,3,FALSE) -> 76 | E22: 40 | F22: =VLOOKUP(E22,PipeN!$B$3:$D$48,2,FALSE) -> 1 1/2" | G22: =VLOOKUP(E22,PipeN!$B$3:$D$48,3,FALSE) -> 48.3 | H22: =VLOOKUP(E22,PipeN!$B$72:$D$101,3,FALSE) -> 45 | I22: 95 | J22: 76 | K22: 67
A23: 65 | B23: =VLOOKUP(A23,PipeN!$B$3:$D$48,2,FALSE) -> 2 1/2" | C23: =VLOOKUP(A23,PipeN!$B$3:$D$48,3,FALSE) -> 76.1 | D23: =VLOOKUP(A23,PipeN!$B$72:$D$101,3,FALSE) -> 76 | E23: 32 | F23: =VLOOKUP(E23,PipeN!$B$3:$D$48,2,FALSE) -> 1 1/4" | G23: =VLOOKUP(E23,PipeN!$B$3:$D$48,3,FALSE) -> 42.4 | H23: =VLOOKUP(E23,PipeN!$B$72:$D$101,3,FALSE) -> 38 | I23: 95 | J23: 76 | K23: 64
A24: 65 | B24: =VLOOKUP(A24,PipeN!$B$3:$D$48,2,FALSE) -> 2 1/2" | C24: =VLOOKUP(A24,PipeN!$B$3:$D$48,3,FALSE) -> 76.1 | D24: =VLOOKUP(A24,PipeN!$B$72:$D$101,3,FALSE) -> 76 | E24: 25 | F24: =VLOOKUP(E24,PipeN!$B$3:$D$48,2,FALSE) -> 1" | G24: =VLOOKUP(E24,PipeN!$B$3:$D$48,3,FALSE) -> 33.7 | H24: =VLOOKUP(E24,PipeN!$B$72:$D$101,3,FALSE) -> 32 | J24: 76 | K24: 57
A25: 80 | B25: =VLOOKUP(A25,PipeN!$B$3:$D$48,2,FALSE) -> 3" | C25: =VLOOKUP(A25,PipeN!$B$3:$D$48,3,FALSE) -> 88.9 | D25: =VLOOKUP(A25,PipeN!$B$72:$D$101,3,FALSE) -> 89 | E25: 65 | F25: =VLOOKUP(E25,PipeN!$B$3:$D$48,2,FALSE) -> 2 1/2" | G25: =VLOOKUP(E25,PipeN!$B$3:$D$48,3,FALSE) -> 76.1 | H25: =VLOOKUP(E25,PipeN!$B$72:$D$101,3,FALSE) -> 76 | I25: 114 | J25: 86 | K25: 83
A26: 80 | B26: =VLOOKUP(A26,PipeN!$B$3:$D$48,2,FALSE) -> 3" | C26: =VLOOKUP(A26,PipeN!$B$3:$D$48,3,FALSE) -> 88.9 | D26: =VLOOKUP(A26,PipeN!$B$72:$D$101,3,FALSE) -> 89 | E26: 50 | F26: =VLOOKUP(E26,PipeN!$B$3:$D$48,2,FALSE) -> 2" | G26: =VLOOKUP(E26,PipeN!$B$3:$D$48,3,FALSE) -> 60.3 | H26: =VLOOKUP(E26,PipeN!$B$72:$D$101,3,FALSE) -> 57 | I26: 114 | J26: 86 | K26: 76
A27: 80 | B27: =VLOOKUP(A27,PipeN!$B$3:$D$48,2,FALSE) -> 3" | C27: =VLOOKUP(A27,PipeN!$B$3:$D$48,3,FALSE) -> 88.9 | D27: =VLOOKUP(A27,PipeN!$B$72:$D$101,3,FALSE) -> 89 | E27: 40 | F27: =VLOOKUP(E27,PipeN!$B$3:$D$48,2,FALSE) -> 1 1/2" | G27: =VLOOKUP(E27,PipeN!$B$3:$D$48,3,FALSE) -> 48.3 | H27: =VLOOKUP(E27,PipeN!$B$72:$D$101,3,FALSE) -> 45 | I27: 114 | J27: 86 | K27: 73
A28: 80 | B28: =VLOOKUP(A28,PipeN!$B$3:$D$48,2,FALSE) -> 3" | C28: =VLOOKUP(A28,PipeN!$B$3:$D$48,3,FALSE) -> 88.9 | D28: =VLOOKUP(A28,PipeN!$B$72:$D$101,3,FALSE) -> 89 | E28: 32 | F28: =VLOOKUP(E28,PipeN!$B$3:$D$48,2,FALSE) -> 1 1/4" | G28: =VLOOKUP(E28,PipeN!$B$3:$D$48,3,FALSE) -> 42.4 | H28: =VLOOKUP(E28,PipeN!$B$72:$D$101,3,FALSE) -> 38 | J28: 86 | K28: 70
A29: 100 | B29: =VLOOKUP(A29,PipeN!$B$3:$D$48,2,FALSE) -> 4" | C29: =VLOOKUP(A29,PipeN!$B$3:$D$48,3,FALSE) -> 114.3 | D29: =VLOOKUP(A29,PipeN!$B$72:$D$101,3,FALSE) -> 108 | E29: 80 | F29: =VLOOKUP(E29,PipeN!$B$3:$D$48,2,FALSE) -> 3" | G29: =VLOOKUP(E29,PipeN!$B$3:$D$48,3,FALSE) -> 88.9 | H29: =VLOOKUP(E29,PipeN!$B$72:$D$101,3,FALSE) -> 89 | I29: 152 | J29: 105 | K29: 98
A30: 100 | B30: =VLOOKUP(A30,PipeN!$B$3:$D$48,2,FALSE) -> 4" | C30: =VLOOKUP(A30,PipeN!$B$3:$D$48,3,FALSE) -> 114.3 | D30: =VLOOKUP(A30,PipeN!$B$72:$D$101,3,FALSE) -> 108 | E30: 65 | F30: =VLOOKUP(E30,PipeN!$B$3:$D$48,2,FALSE) -> 2 1/2" | G30: =VLOOKUP(E30,PipeN!$B$3:$D$48,3,FALSE) -> 76.1 | H30: =VLOOKUP(E30,PipeN!$B$72:$D$101,3,FALSE) -> 76 | I30: 152 | J30: 105 | K30: 95
A31: 100 | B31: =VLOOKUP(A31,PipeN!$B$3:$D$48,2,FALSE) -> 4" | C31: =VLOOKUP(A31,PipeN!$B$3:$D$48,3,FALSE) -> 114.3 | D31: =VLOOKUP(A31,PipeN!$B$72:$D$101,3,FALSE) -> 108 | E31: 50 | F31: =VLOOKUP(E31,PipeN!$B$3:$D$48,2,FALSE) -> 2" | G31: =VLOOKUP(E31,PipeN!$B$3:$D$48,3,FALSE) -> 60.3 | H31: =VLOOKUP(E31,PipeN!$B$72:$D$101,3,FALSE) -> 57 | I31: 152 | J31: 105 | K31: 89
A32: 100 | B32: =VLOOKUP(A32,PipeN!$B$3:$D$48,2,FALSE) -> 4" | C32: =VLOOKUP(A32,PipeN!$B$3:$D$48,3,FALSE) -> 114.3 | D32: =VLOOKUP(A32,PipeN!$B$72:$D$101,3,FALSE) -> 108 | E32: 40 | F32: =VLOOKUP(E32,PipeN!$B$3:$D$48,2,FALSE) -> 1 1/2" | G32: =VLOOKUP(E32,PipeN!$B$3:$D$48,3,FALSE) -> 48.3 | H32: =VLOOKUP(E32,PipeN!$B$72:$D$101,3,FALSE) -> 45 | J32: 105 | K32: 86
A33: 125 | B33: =VLOOKUP(A33,PipeN!$B$3:$D$48,2,FALSE) -> 5" | C33: =VLOOKUP(A33,PipeN!$B$3:$D$48,3,FALSE) -> 139.7 | D33: =VLOOKUP(A33,PipeN!$B$72:$D$101,3,FALSE) -> 133 | E33: 100 | F33: =VLOOKUP(E33,PipeN!$B$3:$D$48,2,FALSE) -> 4" | G33: =VLOOKUP(E33,PipeN!$B$3:$D$48,3,FALSE) -> 114.3 | H33: =VLOOKUP(E33,PipeN!$B$72:$D$101,3,FALSE) -> 108 | I33: 190 | J33: 124 | K33: 117
A34: 125 | B34: =VLOOKUP(A34,PipeN!$B$3:$D$48,2,FALSE) -> 5" | C34: =VLOOKUP(A34,PipeN!$B$3:$D$48,3,FALSE) -> 139.7 | D34: =VLOOKUP(A34,PipeN!$B$72:$D$101,3,FALSE) -> 133 | E34: 80 | F34: =VLOOKUP(E34,PipeN!$B$3:$D$48,2,FALSE) -> 3" | G34: =VLOOKUP(E34,PipeN!$B$3:$D$48,3,FALSE) -> 88.9 | H34: =VLOOKUP(E34,PipeN!$B$72:$D$101,3,FALSE) -> 89 | I34: 190 | J34: 124 | K34: 111
A35: 125 | B35: =VLOOKUP(A35,PipeN!$B$3:$D$48,2,FALSE) -> 5" | C35: =VLOOKUP(A35,PipeN!$B$3:$D$48,3,FALSE) -> 139.7 | D35: =VLOOKUP(A35,PipeN!$B$72:$D$101,3,FALSE) -> 133 | E35: 65 | F35: =VLOOKUP(E35,PipeN!$B$3:$D$48,2,FALSE) -> 2 1/2" | G35: =VLOOKUP(E35,PipeN!$B$3:$D$48,3,FALSE) -> 76.1 | H35: =VLOOKUP(E35,PipeN!$B$72:$D$101,3,FALSE) -> 76 | I35: 190 | J35: 124 | K35: 108
A36: 125 | B36: =VLOOKUP(A36,PipeN!$B$3:$D$48,2,FALSE) -> 5" | C36: =VLOOKUP(A36,PipeN!$B$3:$D$48,3,FALSE) -> 139.7 | D36: =VLOOKUP(A36,PipeN!$B$72:$D$101,3,FALSE) -> 133 | E36: 50 | F36: =VLOOKUP(E36,PipeN!$B$3:$D$48,2,FALSE) -> 2" | G36: =VLOOKUP(E36,PipeN!$B$3:$D$48,3,FALSE) -> 60.3 | H36: =VLOOKUP(E36,PipeN!$B$72:$D$101,3,FALSE) -> 57 | J36: 124 | K36: 105
A37: 150 | B37: =VLOOKUP(A37,PipeN!$B$3:$D$48,2,FALSE) -> 6" | C37: =VLOOKUP(A37,PipeN!$B$3:$D$48,3,FALSE) -> 168.3 | D37: =VLOOKUP(A37,PipeN!$B$72:$D$101,3,FALSE) -> 159 | E37: 125 | F37: =VLOOKUP(E37,PipeN!$B$3:$D$48,2,FALSE) -> 5" | G37: =VLOOKUP(E37,PipeN!$B$3:$D$48,3,FALSE) -> 139.7 | H37: =VLOOKUP(E37,PipeN!$B$72:$D$101,3,FALSE) -> 133 | I37: 229 | J37: 143 | K37: 137
A38: 150 | B38: =VLOOKUP(A38,PipeN!$B$3:$D$48,2,FALSE) -> 6" | C38: =VLOOKUP(A38,PipeN!$B$3:$D$48,3,FALSE) -> 168.3 | D38: =VLOOKUP(A38,PipeN!$B$72:$D$101,3,FALSE) -> 159 | E38: 100 | F38: =VLOOKUP(E38,PipeN!$B$3:$D$48,2,FALSE) -> 4" | G38: =VLOOKUP(E38,PipeN!$B$3:$D$48,3,FALSE) -> 114.3 | H38: =VLOOKUP(E38,PipeN!$B$72:$D$101,3,FALSE) -> 108 | I38: 229 | J38: 143 | K38: 130
A39: 150 | B39: =VLOOKUP(A39,PipeN!$B$3:$D$48,2,FALSE) -> 6" | C39: =VLOOKUP(A39,PipeN!$B$3:$D$48,3,FALSE) -> 168.3 | D39: =VLOOKUP(A39,PipeN!$B$72:$D$101,3,FALSE) -> 159 | E39: 80 | F39: =VLOOKUP(E39,PipeN!$B$3:$D$48,2,FALSE) -> 3" | G39: =VLOOKUP(E39,PipeN!$B$3:$D$48,3,FALSE) -> 88.9 | H39: =VLOOKUP(E39,PipeN!$B$72:$D$101,3,FALSE) -> 89 | I39: 229 | J39: 143 | K39: 124
A40: 150 | B40: =VLOOKUP(A40,PipeN!$B$3:$D$48,2,FALSE) -> 6" | C40: =VLOOKUP(A40,PipeN!$B$3:$D$48,3,FALSE) -> 168.3 | D40: =VLOOKUP(A40,PipeN!$B$72:$D$101,3,FALSE) -> 159 | E40: 65 | F40: =VLOOKUP(E40,PipeN!$B$3:$D$48,2,FALSE) -> 2 1/2" | G40: =VLOOKUP(E40,PipeN!$B$3:$D$48,3,FALSE) -> 76.1 | H40: =VLOOKUP(E40,PipeN!$B$72:$D$101,3,FALSE) -> 76 | J40: 143 | K40: 121
...

Sheet test
